Workbook
Name trm: Parameters!$A$12
Name trm: Parameters!$A$12

Sheet Total
B2: Costo Total
B3: Item | C3: Costo Unitario USD | D3: Costo Unitario COP | E3: Cantidad | F3: Costo Total USD | G3: Costo Total COP | H3: Opción | I3: Margen | J3: Descuento
B4: Implementación | C4: ='Professional Services'!H14 -> 3417.1429 | D4: =C4*trm -> 13668571 | E4: 1 | F4: =C4*E4 -> 3417.1429 | G4: =F4*trm -> 13668571 | I4: 1.23 | J4: 0.05
B5: Cloud Implementación | C5: =VLOOKUP(H5,Cloud!B2:F5,5) -> 1815.7878 | D5: =C5*trm -> 7263151.2 | E5: 1 | F5: =C5*E5 -> 1815.7878 | G5: =F5*trm -> 7263151.2 | H5: Opcion 2 | I5: 0.0753 | J5: 0
B6: Operación | C6: =IFERROR('Professional Services'!H15/E6,0) -> 0 | D6: =C6*trm -> 0 | E6: 0 | F6: =C6*E6 -> 0 | G6: =F6*trm -> 0 | I6: 1.23 | J6: 0
B7: Cloud Operación | C7: =VLOOKUP(H7,Cloud!B2:F4,5) -> 1815.7878 | D7: =C7*trm -> 7263151.2 | E7: 0 | F7: =C7*E7 -> 0 | G7: =F7*trm -> 0 | H7: Opcion 1 | I7: 0.0753 | J7: 0
B8: Houndoc SaaS | C8: =ROUND(C18/(1+I8),0) -> 260 | D8: =C8*trm -> 1040000 | E8: 0 | F8: =C8*E8 -> 0 | G8: =F8*trm -> 0 | H8: 1-10 | I8: 9 | J8: 0
B9: Otros Vendors | C9: ='Other Vendors'!F6 -> 0 | D9: =C9*trm -> 0 | E9: =IF(C9>0,1,0) -> 0 | F9: =C9*E9 -> 0 | G9: =F9*trm -> 0 | I9: ='Other Vendors'!H6 -> 0 | J9: 0
B10: Total | F10: =SUM(F4:F9) -> 5232.9307 | G10: =SUM(G4:G9) -> 20931723
B12: Valor de venta Total
B13: Item | C13: Valor Unitario USD | D13: Valor Unitario COP | E13: Cantidad | F13: Valor Total USD | G13: Valor Total COP | H13: IVA | I13: Valor Total con IVA | J13: Gross Margin Sin IVA | K13: Revenue Allocation
B14: Implementación | C14: =ROUND((C4*(1+I4))*(1-J4),0) -> 7239 | D14: =C14*trm -> 28956000 | E14: =E4 -> 1 | F14: =C14*E14 -> 7239 | G14: =F14*trm -> 28956000 | H14: =G14*0.19 -> 5501640 | I14: =G14+H14 -> 34457640 | J14: =IFERROR(1-(F4/F14),0) -> 0.52795374 | K14: =IFERROR((G14/$G$20),0) -> 0.78753264
B15: Cloud Implementación | C15: =ROUND((C5*(1+I5))*(1-J5),0) -> 1953 | D15: =C15*trm -> 7812000 | E15: =E5 -> 1 | F15: =C15*E15 -> 1953 | G15: =F15*trm -> 7812000 | H15: =G15*0 -> 0 | I15: =G15+H15 -> 7812000 | J15: =IFERROR(1-(F5/F15),0) -> 0.070257143 | K15: =IFERROR((G15/$G$20),0) -> 0.21246736
B16: Operación | C16: =ROUND((C6*(1+I6))*(1-J6),0) -> 0 | D16: =C16*trm -> 0 | E16: =E6 -> 0 | F16: =C16*E16 -> 0 | G16: =F16*trm -> 0 | H16: =G16*0.19 -> 0 | I16: =G16+H16 -> 0 | J16: =IFERROR(1-(F6/F16),0) -> 0 | K16: =IFERROR((G16/$G$20),0) -> 0
B17: Cloud Operación | C17: =ROUND((C7*(1+I7))*(1-J7),0) -> 1953 | D17: =C17*trm -> 7812000 | E17: =E7 -> 0 | F17: =C17*E17 -> 0 | G17: =F17*trm -> 0 | H17: =G17*0 -> 0 | I17: =G17+H17 -> 0 | J17: =IFERROR(1-(F7/F17),0) -> 0 | K17: =IFERROR((G17/$G$20),0) -> 0
B18: Houndoc SaaS | C18: =ROUND((IFERROR(_xlfn.XLOOKUP(H8,'Houndoc SaaS'!A2:A7,'Houndoc SaaS'!C2:C7),0))*(1-J8),0) -> 2600 | D18: =C18*trm -> 10400000 | E18: =E8 -> 0 | F18: =C18*E18 -> 0 | G18: =F18*trm -> 0 | H18: 0 | I18: =G18+H18 -> 0 | J18: =IFERROR(1-(F8/F18),0) -> 0 | K18: =IFERROR((G18/$G$20),0) -> 0
B19: Otros Vendors | C19: =ROUND((C9*(1+I9))*(1-J9),0) -> 0 | D19: =C19*trm -> 0 | E19: =E9 -> 0 | F19: =C19*E19 -> 0 | G19: =F19*trm -> 0 | H19: ='Other Vendors'!L6*trm -> 0 | I19: =G19+H19 -> 0 | J19: =IFERROR(1-(F9/F19),0) -> 0 | K19: =IFERROR((G19/$G$20),0) -> 0
B20: Total | E20: =E10 -> 0 | F20: =SUM(F14:F19) -> 9192 | G20: =SUM(G14:G19) -> 36768000 | H20: =SUM(H14:H19) -> 5501640 | I20: =SUM(I14:I19) -> 42269640 | J20: =1-(F10/F20) -> 0.43070815 | K20: =SUM(K14:K19) -> 1
B22: CAPEX
B23: Item | C23: Valor Unitario USD | D23: Valor Unitario COP | E23: Cantidad | F23: Valor Total USD | G23: Valor Total COP | H23: IVA | I23: Valor Total con IVA
B24: Implementación | C24: =C14 -> 7239 | D24: =D14 -> 28956000 | E24: =E14 -> 1 | F24: =F14 -> 7239 | G24: =G14 -> 28956000 | H24: =H14 -> 5501640 | I24: =I14 -> 34457640
B25: Cloud Implementación | C25: =C15 -> 1953 | D25: =D15 -> 7812000 | E25: =E5 -> 1 | F25: =F15 -> 1953 | G25: =G15 -> 7812000 | H25: 0 | I25: =I15 -> 7812000
B26: Total | F26: =SUM(F24:F25) -> 9192 | G26: =SUM(G24:G25) -> 36768000 | H26: =SUM(H24:H25) -> 5501640 | I26: =SUM(I24:I25) -> 42269640
B28: OPEX
B29: Item | C29: Valor Unitario USD | D29: Valor Unitario COP | E29: Cantidad | F29: Valor Total USD | G29: Valor Total COP | H29: IVA | I29: Valor Total con IVA
B30: Operación | C30: =C16 -> 0 | D30: =D16 -> 0 | E30: =E16 -> 0 | F30: =F16 -> 0 | G30: =G16 -> 0 | H30: =H16 -> 0 | I30: =I16 -> 0
B31: Cloud Operación | C31: =C17 -> 1953 | D31: =D17 -> 7812000 | E31: =E17 -> 0 | F31: =F17 -> 0 | G31: =G17 -> 0 | H31: =H17 -> 0 | I31: =I17 -> 0
B32: Houndoc SaaS | C32: =C18 -> 2600 | D32: =D18 -> 10400000 | E32: =E18 -> 0 | F32: =F18 -> 0 | G32: =G18 -> 0 | H32: =H18 -> 0 | I32: =I18 -> 0
B33: Otros Vendors | C33: =C19 -> 0 | D33: =D19 -> 0 | E33: =E19 -> 0 | F33: =F19 -> 0 | G33: =G19 -> 0 | H33: =H19 -> 0 | I33: =I19 -> 0
B34: Total | F34: =SUM(F30:F33) -> 0 | G34: =SUM(G30:G33) -> 0 | H34: =SUM(H30:H33) -> 0 | I34: =SUM(I30:I33) -> 0

Sheet Propuesta
A1: Item | B1: Valor Unitario | C1: Cantidad | D1: Valor Total | E1: IVA | F1: Valor Total con IVA
A2: Implementación | B2: =Total!D14 -> 28956000 | C2: =Total!E14 -> 1 | D2: =Total!G14 -> 28956000 | E2: =Total!H14 -> 5501640 | F2: =Total!I14 -> 34457640
A3: Cloud Implementación | B3: =Total!D15 -> 7812000 | C3: =Total!E15 -> 1 | D3: =Total!I15 -> 7812000 | E3: =Total!H15 -> 0 | F3: =Total!I15 -> 7812000
A4: Operación | B4: =Total!D16 -> 0 | C4: =Total!E16 -> 0 | D4: =Total!G16 -> 0 | E4: =Total!H16 -> 0 | F4: =Total!I16 -> 0
A5: Cloud Operación | B5: =Total!D17 -> 7812000 | C5: =Total!E17 -> 0 | D5: =Total!G17 -> 0 | E5: =Total!H17 -> 0 | F5: =Total!I17 -> 0
A6: Houndoc SaaS | B6: =Total!D18 -> 10400000 | C6: =Total!E18 -> 0 | D6: =Total!G18 -> 0 | E6: =Total!H18 -> 0 | F6: =Total!I18 -> 0
A7: Otros Vendors | B7: =Total!D19 -> 0 | C7: =Total!E19 -> 0 | D7: =Total!G19 -> 0 | E7: =Total!H19 -> 0 | F7: =Total!I19 -> 0
A8: Total | D8: =SUM(D2:D7) -> 36768000 | E8: =SUM(E2:E7) -> 5501640 | F8: =SUM(F2:F7) -> 42269640
A12: =Total!B22 -> CAPEX
A13: =Total!B23 -> Item | B13: =Total!D23 -> Valor Unitario COP | C13: =Total!E23 -> Cantidad | D13: =Total!G23 -> Valor Total COP | E13: =Total!H23 -> IVA | F13: =Total!I23 -> Valor Total con IVA
A14: =Total!B24 -> Implementación | B14: =Total!D24 -> 28956000 | C14: =Total!E24 -> 1 | D14: =Total!G24 -> 28956000 | E14: =Total!H24 -> 5501640 | F14: =Total!I24 -> 34457640
A15: =Total!B25 -> Cloud Implementación | B15: =Total!D25 -> 7812000 | C15: =Total!E25 -> 1 | D15: =Total!G25 -> 7812000 | E15: =Total!H25 -> 0 | F15: =Total!I25 -> 7812000
A16: =Total!B26 -> Total | D16: =SUM(D14:D15) -> 36768000 | E16: =SUM(E14:E15) -> 5501640 | F16: =SUM(F14:F15) -> 42269640
A20: =Total!B28 -> OPEX
A21: =Total!B29 -> Item | B21: =Total!D29 -> Valor Unitario COP | C21: =Total!E29 -> Cantidad | D21: =Total!G29 -> Valor Total COP | E21: =Total!H29 -> IVA | F21: =Total!I29 -> Valor Total con IVA
A22: =Total!B30 -> Operación | B22: =Total!D30 -> 0 | C22: =Total!E30 -> 0 | D22: =Total!G30 -> 0 | E22: =Total!H30 -> 0 | F22: =Total!I30 -> 0
A23: =Total!B31 -> Cloud Operación | B23: =Total!D31 -> 7812000 | C23: =Total!E31 -> 0 | D23: =Total!G31 -> 0 | E23: =Total!H31 -> 0 | F23: =Total!I31 -> 0
A24: =Total!B32 -> Houndoc SaaS | B24: =Total!D32 -> 10400000 | C24: =Total!E32 -> 0 | D24: =Total!G32 -> 0 | E24: =Total!H32 -> 0 | F24: =Total!I32 -> 0
A25: =Total!B33 -> Otros Vendors | B25: =Total!D33 -> 0 | C25: =Total!E33 -> 0 | D25: =Total!G33 -> 0 | E25: =Total!H33 -> 0 | F25: =Total!I33 -> 0
A26: =Total!B34 -> Total | D26: =SUM(D22:D25) -> 0 | E26: =SUM(E22:E25) -> 0 | F26: =SUM(F22:F25) -> 0

Sheet HL Plan
A1: Actividad | B1: M1 | C1: M2 | D1: M3 | E1: M4 | F1: M5 | G1: M6 | H1: M7 | I1: M8 | J1: M9 | K1: M10 | L1: M11 | M1: M12 | N1: M13 | O1: M14
A2: Selección del servicio candidato | B2: 1
A3: Análisis técnico del servicio | B3: 1
A4: Definición del enfoque de modernización y migración | B4: 1
A5: Modernización del servicio | B5: 1
A6: Preparación para la migración a ROSA | B6: 1
A7: Migración del servicio a ROSA | B7: 1
A8: Preparación del plan de pruebas | B8: 1
A9: Ejecución de pruebas del servicio | B9: 1
A10: Consolidación de resultados del PoC | B10: 1
A11: Cierre de la PoC | B11: 1
A12: Cloud | B12: 4
A13: Otros vendors | B13: 5
A15: 1-Implementacion
A16: 2-Soporte
A17: 3-Houndoc
A18: 4-Cloud
A19: 5-Otros vendors

Sheet HL Plan Semana
A1: Actividad | B1: S1 | C1: S2 | D1: S3 | E1: S4
A2: Selección del servicio candidato | B2: 1
A3: Análisis técnico del servicio | B3: 1 | K3: Tipo | L3: Titulo | M3: Descripción | N3: Tipo de Equipo | O3: N° Equipos | P3: N° Meses | Q3: Total Equipo*Meses | R3: Costo USD | S3: Costo COP | T3: Valor Venta USD | U3: Valor Venta COP
A4: Definición del enfoque de modernización y migración | C4: 1 | K4: Implementación | L4: Modernización del servicio | M4: Adaptación del servicio desde Fuse para su ejecución sobre OpenShift Application Foundations. | N4: Software | O4: 0.5 | P4: 0.25 | Q4: 0.125 | R4: 1748.94 | S4: 7870230 | T4: 3900.1362 | U4: 17550613
A5: Modernización del servicio | C5: 1
A6: Preparación para la migración a ROSA | D6: 1
A7: Migración del servicio a ROSA | D7: 1
A8: Preparación del plan de pruebas | D8: 1
A9: Ejecución de pruebas del servicio | E9: 1
A10: Consolidación de resultados del PoC | E10: 1
A11: Cierre de la PoC | E11: 1
A12: Cloud | E12: 4
A13: Otros vendors | E13: 5
A15: 1-Implementacion
A16: 2-Soporte
A17: 3-Houndoc
A18: 4-Cloud
A19: 5-Otros vendors

Sheet Professional Services
A1: Tipo | B1: Titulo | C1: Descripción | D1: Tipo de Equipo | E1: N° Equipos | F1: N° Meses | G1: Total Equipo*Meses | H1: Costo USD | I1: Costo COP | J1: Valor Venta USD | K1: Valor Venta COP
A2: Implementación | B2: Validación de Arquitectura Base para ROSA HCP | C2: Validación del diseño objetivo considerando: Subnets privadas para worker nodes Configuración de VPC existente o dedicada Requisitos de IAM Enfoque de conectividad (VPN/Direct Connect si aplica) Lineamientos de seguridad y cifrado | D2: Software | E2: 0.25 | F2: =(0.25/7)*2 -> 0.071428571 | G2: =E2*F2 -> 0.017857143 | H2: =_xlfn.XLOOKUP(D2, Parameters!$A$6:$A$9, Parameters!$B$6:$B$9) * G2 -> 297.14286 | I2: =H2*trm -> 1188571.4 | J2: =IF(H2=0, 0, H2*(1+Total!$I$4)*(1-Total!$J$4)) -> 629.49714 | K2: =IF(I2=0, 0, I2*(1+Total!$I$4)*(1-Total!$J$4)) -> 2517988.6
A3: Implementación | B3: Habilitación de ROSA HCP y Prerrequisitos Técnicos | C3: Validación de cuotas AWS (EC2, ELB, EBS, VPC) Validación de roles requeridos para HCP Configuración ROSA CLI Habilitación del servicio en la cuenta Validación de permisos y políticas | D3: Software | E3: 0.25 | F3: =(0.25/7)*2 -> 0.071428571 | G3: =E3*F3 -> 0.017857143 | H3: =_xlfn.XLOOKUP(D3, Parameters!$A$6:$A$9, Parameters!$B$6:$B$9) * G3 -> 297.14286 | I3: =H3*trm -> 1188571.4 | J3: =IF(H3=0, 0, H3*(1+Total!$I$4)*(1-Total!$J$4)) -> 629.49714 | K3: =IF(I3=0, 0, I3*(1+Total!$I$4)*(1-Total!$J$4)) -> 2517988.6
A4: Implementación | B4: Creación del Cluster ROSA HCP | C4: Creación del cluster HCP Validación del estado Ready Configuración básica de acceso (oc login) Validación de worker nodes Verificación de networking y salida a dependencias | D4: Software | E4: 0.25 | F4: =(0.25/7)*2 -> 0.071428571 | G4: =E4*F4 -> 0.017857143 | H4: =_xlfn.XLOOKUP(D4, Parameters!$A$6:$A$9, Parameters!$B$6:$B$9) * G4 -> 297.14286 | I4: =H4*trm -> 1188571.4 | J4: =IF(H4=0, 0, H4*(1+Total!$I$4)*(1-Total!$J$4)) -> 629.49714 | K4: =IF(I4=0, 0, I4*(1+Total!$I$4)*(1-Total!$J$4)) -> 2517988.6
A5: Implementación | B5: Configuración Base del Entorno OpenShift | C5: Creación de namespace del servicio Configuración de secrets Configuración de service accounts Configuración de certificados si aplica Validación de acceso a dependencias | D5: Software | E5: 0.25 | F5: =(0.25/7)*2 -> 0.071428571 | G5: =E5*F5 -> 0.017857143 | H5: =_xlfn.XLOOKUP(D5, Parameters!$A$6:$A$9, Parameters!$B$6:$B$9) * G5 -> 297.14286 | I5: =H5*trm -> 1188571.4 | J5: =IF(H5=0, 0, H5*(1+Total!$I$4)*(1-Total!$J$4)) -> 629.49714 | K5: =IF(I5=0, 0, I5*(1+Total!$I$4)*(1-Total!$J$4)) -> 2517988.6
A6: Implementación | B6: Despliegue del Servicio Migrado en ROSA HCP | C6: Deploy del artefacto (Docker o manifiestos) Configuración de variables de entorno Ajustes de recursos (CPU/memoria) Configuración de Service / Route / Ingress Validación técnica post-deploy | D6: Software | E6: 0.25 | F6: =(0.25/7)*3 -> 0.10714286 | G6: =E6*F6 -> 0.026785714 | H6: =_xlfn.XLOOKUP(D6, Parameters!$A$6:$A$9, Parameters!$B$6:$B$9) * G6 -> 445.71429 | I6: =H6*trm -> 1782857.1 | J6: =IF(H6=0, 0, H6*(1+Total!$I$4)*(1-Total!$J$4)) -> 944.24571 | K6: =IF(I6=0, 0, I6*(1+Total!$I$4)*(1-Total!$J$4)) -> 3776982.9
A7: Implementación | B7: Acompañamiento Técnico a Pruebas | C7: Soporte durante ejecución del set de pruebas del cliente Monitoreo de métricas E2E (p85 ≤ 800 ms, promedio ≤ 400 ms) Validación de estabilidad del cluster Ajustes menores de configuración si se requieren | D7: Software | E7: 0.25 | F7: =(0.25/7)*10 -> 0.35714286 | G7: =E7*F7 -> 0.089285714 | H7: =_xlfn.XLOOKUP(D7, Parameters!$A$6:$A$9, Parameters!$B$6:$B$9) * G7 -> 1485.7143 | I7: =H7*trm -> 5942857.1 | J7: =IF(H7=0, 0, H7*(1+Total!$I$4)*(1-Total!$J$4)) -> 3147.4857 | K7: =IF(I7=0, 0, I7*(1+Total!$I$4)*(1-Total!$J$4)) -> 12589943
A8: Implementación | B8: Consolidación y Cierre | C8: Recopilación de métricas Validación contra criterios de éxito Documento de conclusiones técnicas Recomendaciones para migración a escala | D8: Software | E8: 0.25 | F8: =(0.25/7)*2 -> 0.071428571 | G8: =E8*F8 -> 0.017857143 | H8: =_xlfn.XLOOKUP(D8, Parameters!$A$6:$A$9, Parameters!$B$6:$B$9) * G8 -> 297.14286 | I8: =H8*trm -> 1188571.4 | J8: =IF(H8=0, 0, H8*(1+Total!$I$4)*(1-Total!$J$4)) -> 629.49714 | K8: =IF(I8=0, 0, I8*(1+Total!$I$4)*(1-Total!$J$4)) -> 2517988.6
G10: Tiempo Implementación Un equipo | H10: =SUMIF(A2:A8,"Implementación", G2:G8) -> 0.20535714
G11: Horas Implementación | H11: =ROUND(H10*160*4,0) -> 131
G12: Horas Operación x Mes | H12: =ROUND(SUM(0)*160*4,0) -> 0
G14: Implementación | H14: =SUMIF(A2:A8,"Implementación", H2:H8) -> 3417.1429 | I14: =SUMIF(A2:A8,"Implementación", I2:I8) -> 13668571
G15: Operación | H15: =SUMIF(A2:A8,"Operación", H2:H8) -> 0 | I15: =SUMIF(A2:A5,"Operación", I2:I5) -> 0
G16: Total SP | H16: =SUM(H14:H15) -> 3417.1429 | I16: =SUM(I14:I15) -> 13668571

Sheet Cloud
A1: Tipo | B1: Opciones | C1: Detalle | D1: Precio Mes | E1: Beneficio | F1: Costo Mes | G1: Margen sugerido | H1: Link Calculadora | I1: Link Diagrama
A2: Operación | B2: Opcion 1 | D2: 1952.46 | E2: 0.07 | F2: =D2*(1-E2) -> 1815.7878 | G2: =ROUND(((D2/F2)-1),4) -> 0.0753 | H2: https://calculator.aws/#/estimate?id=dd8d9356c8f2b076659df2b6615ddc06a02b3d2d
A3: Implementación | B3: Opcion 2 | D3: =D2 -> 1952.46 | E3: 0.07 | F3: =D3*(1-E3) -> 1815.7878 | G3: =IFERROR(ROUND(((D3/F3)-1),4),"NA") -> 0.0753
B4: Opcion 3 | E4: 0.07 | F4: =D4*(1-E4) -> 0 | G4: =IFERROR(ROUND(((D4/F4)-1),4),"NA") -> NA

Sheet Other Vendors
A1: Proveedor | B1: Tipo de Vendor | C1: Servicio | D1: Costo unitario USD | E1: Cantidad | F1: Costo Total USD | G1: Costo Total COP | H1: Margen | I1: Valor Total sin IVA USD | J1: Valor Total sin IVA COP | K1: Gross Margin | L1: IVA | M1: Valor Total con IVA USD | N1: Valor Total con IVA COP
B2: Operación | C2: Adaptación del servicio desde Fuse para su ejecución sobre OpenShift Application Foundations. | D2: 3900 | E2: 0 | F2: =D2*E2 -> 0 | G2: =F2*trm -> 0 | H2: 0.1364 | I2: =F2*(1+H2) -> 0 | J2: =I2*trm -> 0 | K2: =IFERROR(1-(F2/I2),0) -> 0 | L2: =I2*0.19 -> 0 | M2: =I2+L2 -> 0 | N2: =(K2+M2)*trm -> 0
B3: Operación | F3: =D3*E3 -> 0 | G3: =F3*trm -> 0 | H3: 0.1364 | I3: =F3*(1+H3) -> 0 | J3: =I3*trm -> 0 | K3: =IFERROR(1-(F3/I3),0) -> 0 | L3: 0 | M3: =I3+L3 -> 0 | N3: =(K3+M3)*trm -> 0
B4: Operación | F4: =D4*E4 -> 0 | G4: =F4*trm -> 0 | H4: 0.5385 | I4: =F4*(1+H4) -> 0 | J4: =I4*trm -> 0 | K4: =IFERROR(1-(F4/I4),0) -> 0 | L4: =I4*19% -> 0 | M4: =I4+L4 -> 0 | N4: =(K4+M4)*trm -> 0
B5: Operación | F5: =D5*E5 -> 0 | G5: =F5*trm -> 0 | H5: 0.5385 | I5: =F5*(1+H5) -> 0 | J5: =I5*trm -> 0 | K5: =IFERROR(1-(F5/I5),0) -> 0 | L5: =I5*19% -> 0 | M5: =I5+L5 -> 0 | N5: =(K5+M5)*trm -> 0
A6: Total | D6: =SUM(D2:D5) -> 3900 | E6: - | F6: =SUM(F2:F5) -> 0 | G6: =SUM(G2:G5) -> 0 | H6: =IFERROR((I6/F6)-1,0) -> 0 | I6: =SUM(I2:I5) -> 0 | J6: =SUM(J2:J5) -> 0 | K6: =IFERROR(1-(F6/I6),0) -> 0 | L6: =SUM(L2:L5) -> 0 | M6: =SUM(M2:M5) -> 0 | N6: =SUM(N2:N5) -> 0

Sheet Houndoc SaaS
A1: Opciones | B1: Detalle | C1: Precio mensual
A2: 0 | B2: Houndoc - Plataforma Core en la Nube - SAAS. (1-10 Usuarios nombrados) | C2: 0
A3: 1-10 | B3: Houndoc - Plataforma Core en la Nube - SAAS. (1-10 Usuarios nombrados) | C3: 2600
A4: 11-50 | B4: Houndoc - Plataforma Core en la Nube - SAAS. (11-50 Usuarios nombrados) | C4: 5300
A5: 51-100 | B5: Houndoc - Plataforma Core en la Nube - SAAS. (51-100 Usuarios nombrados) | C5: 12100
A6: 100-500 | B6: Houndoc - Plataforma Core en la Nube - SAAS. (100-500 Usuarios nombrados) | C6: 50300
A7: 501-1000 | B7: Houndoc - Plataforma Core en la Nube - SAAS. (501 - 1000 Usuarios Nombrados) | C7: =50300*1.75 -> 88025

Sheet MAP
A1: MAP Phase | B1: Aplica | C1: Valor Sugerido | D1: Valor Real
A2: Assess | B2: No | C2: =IF(B2="Si",$B$6*5%,0) -> 0 | D2: 10000
A3: Mobilize | B3: No | C3: =IF(B3="Si",$B$6*20%,0) -> 0 | D3: 41000
A4: Migrate | B4: No | C4: =IF(B4="Si",$B$6*25%,0) -> 0 | D4: 54000
A6: ARR | B6: =18000*12 -> 216000
A7: Calculator

Sheet Notes
A1: Nombre | B1: Detalle | C1: Link

Sheet Parameters
A1: Tipo Esfuerzo
A2: Implementación
A3: Operación
A5: Tipo Equipo (4 P) | B5: Costo Mes USD | C5: Costo Mes COP | D5: Costo Hora USD | E5: Costo Hora COP | H5: Tipo de Vendor
A6: Software | B6: =D6*640 -> 16640 | C6: =E6*640 -> 66812160 | D6: =ROUND(E6/$B$12,0) -> 26 | E6: 104394 | H6: Implementación
A7: Analítica | B7: =D7*640 -> 16640 | C7: =E7*640 -> 66812160 | D7: =ROUND(E7/$B$12,0) -> 26 | E7: 104394 | H7: Operación
A8: Soporte | B8: =D8*640 -> 16640 | C8: =E8*640 -> 66812160 | D8: =ROUND(E8/$B$12,0) -> 26 | E8: 104394 | H8: CS (Cloud Services)
A9: Semillero | B9: =D9*640 -> 16640 | C9: =E9*640 -> 66812160 | D9: =ROUND(E9/$B$12,0) -> 26 | E9: 104394 | H9: SW (Software)
A11: Valor TRM AWS | B11: Valor TRM PS Belnd
A12: 4000 | B12: 4000
A14: ID Hubspot | B14: A4132
A15: Cliente | B15: DIAN
A16: Proyecto | B16: Portal
A17: Fecha Inicio | B17: 2025_08_Ago
A18: Tiempo Proyecto | B18: =COUNTA('HL Plan'!1:1)-1 -> 14
A19: Tiempo Implementación | B19: =SUM(44:44) -> 1
A20: Mes Inicio Implementacion | B20: =MATCH(1,44:44, 0)-1 -> 1
A21: Tiempo Operación | B21: =SUM(45:45) -> 0
A22: Mes Inicio Operacion | B22: =MATCH(1,45:45, 0)-1 -> #N/A
A23: Tiempo SW (Software) | B23: =SUM(46:46) -> 0
A24: Mes Inicio SW | B24: =MATCH(1,46:46, 0)-1 -> #N/A
A25: Tiempo CS (Cloud Services) | B25: =SUM(47:47) -> 1
A26: Mes Inicio CS | B26: =MATCH(1,47:47, 0)-1 -> 1
A27: Tiempo Cloud Implementación | B27: =Total!E5 -> 1
A28: Mes Inicio OV | B28: =MATCH(1,48:48, 0)-1 -> 1
A29: Tiempo Otros Vendors | B29: =SUM(48:48) -> 1
A31: Implementación | B31: Valor de Implementación
B32: otros vendors (hardware de un solo pago o servicios profesionales)
A33: Operación | B33: Valor de Operación
B34: Otros vendors (Personal que se tenga que contratar para llevar a cabo actividades post implementación)
B35: Otros
A36: CS (Cloud Services) | B36: Valor de Cloud
B37: Houndoc (Marketplace)
B38: Compras Marketplace
A39: SW (Software) | B39: Valor Licencia de Houndoc (Directo)
B40: Otros vendors (Software Licenciado con cobro mensual)
A44: Tiempo Implementación | B44: =IF(ISERROR(COUNTIF('HL Plan'!B1:B102,1)), 0, IF(COUNTIF('HL Plan'!B1:B102,1)>0,1,0)) -> 1 | C44: =IF(ISERROR(COUNTIF('HL Plan'!C1:C102,1)), 0, IF(COUNTIF('HL Plan'!C1:C102,1)>0,1,0)) -> 0 | D44: =IF(ISERROR(COUNTIF('HL Plan'!D1:D102,1)), 0, IF(COUNTIF('HL Plan'!D1:D102,1)>0,1,0)) -> 0 | E44: =IF(ISERROR(COUNTIF('HL Plan'!E1:E102,1)), 0, IF(COUNTIF('HL Plan'!E1:E102,1)>0,1,0)) -> 0 | F44: =IF(ISERROR(COUNTIF('HL Plan'!F1:F102,1)), 0, IF(COUNTIF('HL Plan'!F1:F102,1)>0,1,0)) -> 0 | G44: =IF(ISERROR(COUNTIF('HL Plan'!G1:G102,1)), 0, IF(COUNTIF('HL Plan'!G1:G102,1)>0,1,0)) -> 0 | H44: =IF(ISERROR(COUNTIF('HL Plan'!H1:H102,1)), 0, IF(COUNTIF('HL Plan'!H1:H102,1)>0,1,0)) -> 0 | I44: =IF(ISERROR(COUNTIF('HL Plan'!I1:I102,1)), 0, IF(COUNTIF('HL Plan'!I1:I102,1)>0,1,0)) -> 0 | ... BO44: =IF(ISERROR(COUNTIF('HL Plan'!BO1:BO102,1)), 0, IF(COUNTIF('HL Plan'!BO1:BO102,1)>0,1,0)) -> 0 | BP44: =IF(ISERROR(COUNTIF('HL Plan'!BO1:BO102,1)), 0, IF(COUNTIF('HL Plan'!BO1:BO102,1)>0,1,0)) -> 0 | BQ44: =IF(ISERROR(COUNTIF('HL Plan'!BP1:BP102,1)), 0, IF(COUNTIF('HL Plan'!BP1:BP102,1)>0,1,0)) -> 0 | BR44: =IF(ISERROR(COUNTIF('HL Plan'!BQ1:BQ102,1)), 0, IF(COUNTIF('HL Plan'!BQ1:BQ102,1)>0,1,0)) -> 0 | BS44: =IF(ISERROR(COUNTIF('HL Plan'!BR1:BR102,1)), 0, IF(COUNTIF('HL Plan'!BR1:BR102,1)>0,1,0)) -> 0 | BT44: =IF(ISERROR(COUNTIF('HL Plan'!BS1:BS102,1)), 0, IF(COUNTIF('HL Plan'!BS1:BS102,1)>0,1,0)) -> 0 | BU44: =IF(ISERROR(COUNTIF('HL Plan'!BT1:BT102,1)), 0, IF(COUNTIF('HL Plan'!BT1:BT102,1)>0,1,0)) -> 0 | BV44: =IF(ISERROR(COUNTIF('HL Plan'!BU1:BU102,1)), 0, IF(COUNTIF('HL Plan'!BU1:BU102,1)>0,1,0)) -> 0 | BW44: =IF(ISERROR(COUNTIF('HL Plan'!BV1:BV102,1)), 0, IF(COUNTIF('HL Plan'!BV1:BV102,1)>0,1,0)) -> 0 | ... CI44: =IF(ISERROR(COUNTIF('HL Plan'!CH1:CH102,1)), 0, IF(COUNTIF('HL Plan'!CH1:CH102,1)>0,1,0)) -> 0
A45: Tiempo Operación | B45: =IF(ISERROR(COUNTIF('HL Plan'!B1:B102,2)), 0, IF(COUNTIF('HL Plan'!B1:B102,2)>0,1,0)) -> 0 | C45: =IF(ISERROR(COUNTIF('HL Plan'!C1:C102,2)), 0, IF(COUNTIF('HL Plan'!C1:C102,2)>0,1,0)) -> 0 | D45: =IF(ISERROR(COUNTIF('HL Plan'!D1:D102,2)), 0, IF(COUNTIF('HL Plan'!D1:D102,2)>0,1,0)) -> 0 | E45: =IF(ISERROR(COUNTIF('HL Plan'!E1:E102,2)), 0, IF(COUNTIF('HL Plan'!E1:E102,2)>0,1,0)) -> 0 | F45: =IF(ISERROR(COUNTIF('HL Plan'!F1:F102,2)), 0, IF(COUNTIF('HL Plan'!F1:F102,2)>0,1,0)) -> 0 | G45: =IF(ISERROR(COUNTIF('HL Plan'!G1:G102,2)), 0, IF(COUNTIF('HL Plan'!G1:G102,2)>0,1,0)) -> 0 | H45: =IF(ISERROR(COUNTIF('HL Plan'!H1:H102,2)), 0, IF(COUNTIF('HL Plan'!H1:H102,2)>0,1,0)) -> 0 | I45: =IF(ISERROR(COUNTIF('HL Plan'!I1:I102,2)), 0, IF(COUNTIF('HL Plan'!I1:I102,2)>0,1,0)) -> 0 | ... BO45: =IF(ISERROR(COUNTIF('HL Plan'!BO1:BO102,2)), 0, IF(COUNTIF('HL Plan'!BO1:BO102,2)>0,1,0)) -> 0 | BP45: =IF(ISERROR(COUNTIF('HL Plan'!BO1:BO102,2)), 0, IF(COUNTIF('HL Plan'!BO1:BO102,2)>0,1,0)) -> 0 | BQ45: =IF(ISERROR(COUNTIF('HL Plan'!BP1:BP102,2)), 0, IF(COUNTIF('HL Plan'!BP1:BP102,2)>0,1,0)) -> 0 | BR45: =IF(ISERROR(COUNTIF('HL Plan'!BQ1:BQ102,2)), 0, IF(COUNTIF('HL Plan'!BQ1:BQ102,2)>0,1,0)) -> 0 | BS45: =IF(ISERROR(COUNTIF('HL Plan'!BR1:BR102,2)), 0, IF(COUNTIF('HL Plan'!BR1:BR102,2)>0,1,0)) -> 0 | BT45: =IF(ISERROR(COUNTIF('HL Plan'!BS1:BS102,2)), 0, IF(COUNTIF('HL Plan'!BS1:BS102,2)>0,1,0)) -> 0 | BU45: =IF(ISERROR(COUNTIF('HL Plan'!BT1:BT102,2)), 0, IF(COUNTIF('HL Plan'!BT1:BT102,2)>0,1,0)) -> 0 | BV45: =IF(ISERROR(COUNTIF('HL Plan'!BU1:BU102,2)), 0, IF(COUNTIF('HL Plan'!BU1:BU102,2)>0,1,0)) -> 0 | BW45: =IF(ISERROR(COUNTIF('HL Plan'!BV1:BV102,2)), 0, IF(COUNTIF('HL Plan'!BV1:BV102,2)>0,1,0)) -> 0 | ... CI45: =IF(ISERROR(COUNTIF('HL Plan'!CH1:CH102,2)), 0, IF(COUNTIF('HL Plan'!CH1:CH102,2)>0,1,0)) -> 0
A46: Tiempo SW (Software) | B46: =IF(ISERROR(COUNTIF('HL Plan'!B1:B102,3)), 0, IF(COUNTIF('HL Plan'!B1:B102,3)>0,1,0)) -> 0 | C46: =IF(ISERROR(COUNTIF('HL Plan'!C1:C102,3)), 0, IF(COUNTIF('HL Plan'!C1:C102,3)>0,1,0)) -> 0 | D46: =IF(ISERROR(COUNTIF('HL Plan'!D1:D102,3)), 0, IF(COUNTIF('HL Plan'!D1:D102,3)>0,1,0)) -> 0 | E46: =IF(ISERROR(COUNTIF('HL Plan'!E1:E102,3)), 0, IF(COUNTIF('HL Plan'!E1:E102,3)>0,1,0)) -> 0 | F46: =IF(ISERROR(COUNTIF('HL Plan'!F1:F102,3)), 0, IF(COUNTIF('HL Plan'!F1:F102,3)>0,1,0)) -> 0 | G46: =IF(ISERROR(COUNTIF('HL Plan'!G1:G102,3)), 0, IF(COUNTIF('HL Plan'!G1:G102,3)>0,1,0)) -> 0 | H46: =IF(ISERROR(COUNTIF('HL Plan'!H1:H102,3)), 0, IF(COUNTIF('HL Plan'!H1:H102,3)>0,1,0)) -> 0 | I46: =IF(ISERROR(COUNTIF('HL Plan'!I1:I102,3)), 0, IF(COUNTIF('HL Plan'!I1:I102,3)>0,1,0)) -> 0 | ... BO46: =IF(ISERROR(COUNTIF('HL Plan'!BO1:BO102,3)), 0, IF(COUNTIF('HL Plan'!BO1:BO102,3)>0,1,0)) -> 0 | BP46: =IF(ISERROR(COUNTIF('HL Plan'!BO1:BO102,3)), 0, IF(COUNTIF('HL Plan'!BO1:BO102,3)>0,1,0)) -> 0 | BQ46: =IF(ISERROR(COUNTIF('HL Plan'!BP1:BP102,3)), 0, IF(COUNTIF('HL Plan'!BP1:BP102,3)>0,1,0)) -> 0 | BR46: =IF(ISERROR(COUNTIF('HL Plan'!BQ1:BQ102,3)), 0, IF(COUNTIF('HL Plan'!BQ1:BQ102,3)>0,1,0)) -> 0 | BS46: =IF(ISERROR(COUNTIF('HL Plan'!BR1:BR102,3)), 0, IF(COUNTIF('HL Plan'!BR1:BR102,3)>0,1,0)) -> 0 | BT46: =IF(ISERROR(COUNTIF('HL Plan'!BS1:BS102,3)), 0, IF(COUNTIF('HL Plan'!BS1:BS102,3)>0,1,0)) -> 0 | BU46: =IF(ISERROR(COUNTIF('HL Plan'!BT1:BT102,3)), 0, IF(COUNTIF('HL Plan'!BT1:BT102,3)>0,1,0)) -> 0 | BV46: =IF(ISERROR(COUNTIF('HL Plan'!BU1:BU102,3)), 0, IF(COUNTIF('HL Plan'!BU1:BU102,3)>0,1,0)) -> 0 | BW46: =IF(ISERROR(COUNTIF('HL Plan'!BV1:BV102,3)), 0, IF(COUNTIF('HL Plan'!BV1:BV102,3)>0,1,0)) -> 0 | ... CI46: =IF(ISERROR(COUNTIF('HL Plan'!CH1:CH102,3)), 0, IF(COUNTIF('HL Plan'!CH1:CH102,3)>0,1,0)) -> 0
A47: Tiempo CS (Cloud Services) | B47: =IF(ISERROR(COUNTIF('HL Plan'!B1:B102,4)), 0, IF(COUNTIF('HL Plan'!B1:B102,4)>0,1,0)) -> 1 | C47: =IF(ISERROR(COUNTIF('HL Plan'!C1:C102,4)), 0, IF(COUNTIF('HL Plan'!C1:C102,4)>0,1,0)) -> 0 | D47: =IF(ISERROR(COUNTIF('HL Plan'!D1:D102,4)), 0, IF(COUNTIF('HL Plan'!D1:D102,4)>0,1,0)) -> 0 | E47: =IF(ISERROR(COUNTIF('HL Plan'!E1:E102,4)), 0, IF(COUNTIF('HL Plan'!E1:E102,4)>0,1,0)) -> 0 | F47: =IF(ISERROR(COUNTIF('HL Plan'!F1:F102,4)), 0, IF(COUNTIF('HL Plan'!F1:F102,4)>0,1,0)) -> 0 | G47: =IF(ISERROR(COUNTIF('HL Plan'!G1:G102,4)), 0, IF(COUNTIF('HL Plan'!G1:G102,4)>0,1,0)) -> 0 | H47: =IF(ISERROR(COUNTIF('HL Plan'!H1:H102,4)), 0, IF(COUNTIF('HL Plan'!H1:H102,4)>0,1,0)) -> 0 | I47: =IF(ISERROR(COUNTIF('HL Plan'!I1:I102,4)), 0, IF(COUNTIF('HL Plan'!I1:I102,4)>0,1,0)) -> 0 | ... BO47: =IF(ISERROR(COUNTIF('HL Plan'!BO1:BO102,4)), 0, IF(COUNTIF('HL Plan'!BO1:BO102,4)>0,1,0)) -> 0 | BP47: =IF(ISERROR(COUNTIF('HL Plan'!BO1:BO102,4)), 0, IF(COUNTIF('HL Plan'!BO1:BO102,4)>0,1,0)) -> 0 | BQ47: =IF(ISERROR(COUNTIF('HL Plan'!BP1:BP102,4)), 0, IF(COUNTIF('HL Plan'!BP1:BP102,4)>0,1,0)) -> 0 | BR47: =IF(ISERROR(COUNTIF('HL Plan'!BQ1:BQ102,4)), 0, IF(COUNTIF('HL Plan'!BQ1:BQ102,4)>0,1,0)) -> 0 | BS47: =IF(ISERROR(COUNTIF('HL Plan'!BR1:BR102,4)), 0, IF(COUNTIF('HL Plan'!BR1:BR102,4)>0,1,0)) -> 0 | BT47: =IF(ISERROR(COUNTIF('HL Plan'!BS1:BS102,4)), 0, IF(COUNTIF('HL Plan'!BS1:BS102,4)>0,1,0)) -> 0 | BU47: =IF(ISERROR(COUNTIF('HL Plan'!BT1:BT102,4)), 0, IF(COUNTIF('HL Plan'!BT1:BT102,4)>0,1,0)) -> 0 | BV47: =IF(ISERROR(COUNTIF('HL Plan'!BU1:BU102,4)), 0, IF(COUNTIF('HL Plan'!BU1:BU102,4)>0,1,0)) -> 0 | BW47: =IF(ISERROR(COUNTIF('HL Plan'!BV1:BV102,4)), 0, IF(COUNTIF('HL Plan'!BV1:BV102,4)>0,1,0)) -> 0 | ... CI47: =IF(ISERROR(COUNTIF('HL Plan'!CH1:CH102,4)), 0, IF(COUNTIF('HL Plan'!CH1:CH102,4)>0,1,0)) -> 0
...

Sheet Finance
A1: Porcentaje
A2: ID Hubspot | B2: Cliente | C2: Proyecto | D2: Item | E2: Total Porcentaje | F2: =F11 -> 2025_08_Ago | G2: =G11 -> 2025_09_Sep | H2: =H11 -> 2025_10_Oct | I2: =I11 -> 2025_11_Nov | J2: =J11 -> 2025_12_Dic | K2: =K11 -> 2026_01_Ene | L2: =L11 -> 2026_02_Feb | M2: =M11 -> 2026_03_Mar | ... HL2: =HL11 -> 0
A3: =A12 -> A4132 | B3: =$B$25 -> DIAN | C3: =$C$25 -> Portal | D3: Porcentaje Implementación | E3: =SUM(F3:IJ3) -> 1 | F3: 0.16666667 | G3: 0.16666667 | H3: 0.16666667 | I3: 0.16666667 | J3: 0.16666667 | K3: 0.16666667 | L3: 0 | M3: 0 | N3: 0 | O3: 0 | P3: 0 | Q3: 0 | R3: 0 | S3: 0
A4: =$A$12 -> A4132 | B4: =$B$25 -> DIAN | C4: =$C$25 -> Portal | D4: Porcentaje Operación | E4: =SUM(F4:IJ4) -> 1 | F4: 0 | G4: 0 | H4: 0.083333333 | I4: 0.083333333 | J4: 0.083333333 | K4: 0.083333333 | L4: 0.083333333 | M4: 0.083333333 | N4: 0.083333333 | O4: 0.083333333 | P4: 0.083333333 | Q4: 0.083333333 | R4: 0.083333333 | S4: 0.083333333
A5: =$A$12 -> A4132 | B5: =$B$25 -> DIAN | C5: =$C$25 -> Portal | D5: Porcentaje CS (Cloud Services) | E5: =SUM(F5:IJ5) -> 1 | F5: 0 | G5: 0.017481784 | H5: 0.017481784 | I5: 0.087730585 | J5: 0.087730585 | K5: 0.087730585 | L5: 0.087730585 | M5: 0.087730585 | N5: 0.087730585 | O5: 0.087730585 | P5: 0.087730585 | Q5: 0.087730585 | R5: 0.087730585 | S5: 0.087730585
A6: =$A$12 -> A4132 | B6: =$B$25 -> DIAN | C6: =$C$25 -> Portal | D6: Porcentaje SW (Software) | E6: =SUM(F6:IJ6) -> 1 | F6: 0 | G6: 0 | H6: 0.083333333 | I6: 0.083333333 | J6: 0.083333333 | K6: 0.083333333 | L6: 0.083333333 | M6: 0.083333333 | N6: 0.083333333 | O6: 0.083333333 | P6: 0.083333333 | Q6: 0.083333333 | R6: 0.083333333 | S6: 0.083333333
A7: =$A$12 -> A4132 | B7: =$B$25 -> DIAN | C7: =$C$25 -> Portal | D7: Porcentaje Other Vendors | E7: =SUM(F7:IJ7) -> 1 | F7: 1 | G7: 0 | H7: 0 | I7: 0 | J7: 0 | K7: 0 | L7: 0 | M7: 0 | N7: 0 | O7: 0 | P7: 0 | Q7: 0 | R7: 0 | S7: 0
A10: Total
A11: ID Hubspot | B11: Cliente | C11: Proyecto | D11: Item | E11: Total | F11: 2025_08_Ago | G11: 2025_09_Sep | H11: 2025_10_Oct | I11: 2025_11_Nov | J11: 2025_12_Dic | K11: 2026_01_Ene | L11: 2026_02_Feb | M11: 2026_03_Mar | N11: 2026_04_Abr | O11: 2026_05_May | P11: 2026_06_Jun | Q11: 2026_07_Jul | R11: 2026_08_Ago | S11: 2026_09_Sep
A12: =Parameters!B14 -> A4132 | B12: =Parameters!B15 -> DIAN | C12: =Parameters!B16 -> Portal | D12: Implementación | E12: =Total!G14 -> 28956000 | F12: 217920000 | G12: 217920000 | H12: 217920000 | I12: 217920000 | J12: 217920000 | K12: 217920000 | L12: 0 | M12: 0 | N12: 0 | O12: 0 | P12: 0 | Q12: 0 | R12: 0 | S12: 0
A13: =Parameters!B14 -> A4132 | B13: =Parameters!B15 -> DIAN | C13: =Parameters!B16 -> Portal | D13: Operación | E13: =Total!G16 -> 0 | F13: 0 | G13: 0 | H13: 70204500 | I13: 70204500 | J13: 70204500 | K13: 70204500 | L13: 70204500 | M13: 70204500 | N13: 70204500 | O13: 70204500 | P13: 70204500 | Q13: 70204500 | R13: 70204500 | S13: 70204500
A14: =Parameters!B14 -> A4132 | B14: =Parameters!B15 -> DIAN | C14: =Parameters!B16 -> Portal | D14: CS (Cloud Services) | E14: =Total!G15+Total!I17 -> 7812000 | F14: 0 | G14: 22500000 | H14: 22500000 | I14: 112914000 | J14: 112914000 | K14: 112914000 | L14: 112914000 | M14: 112914000 | N14: 112914000 | O14: 112914000 | P14: 112914000 | Q14: 112914000 | R14: 112914000 | S14: 112914000
A15: =Parameters!B14 -> A4132 | B15: =Parameters!B15 -> DIAN | C15: =Parameters!B16 -> Portal | D15: SW (Software) | E15: =Total!G18 -> 0 | F15: 0 | G15: 0 | H15: 11700000 | I15: 11700000 | J15: 11700000 | K15: 11700000 | L15: 11700000 | M15: 11700000 | N15: 11700000 | O15: 11700000 | P15: 11700000 | Q15: 11700000 | R15: 11700000 | S15: 11700000
A16: A4132 | B16: DIAN | C16: Portal | D16: Other Vendors | E16: =Total!G19 -> 0 | F16: 2250072000 | G16: 0 | H16: 0 | I16: 0 | J16: 0 | K16: 0 | L16: 0 | M16: 0 | N16: 0 | O16: 0 | P16: 0 | Q16: 0 | R16: 0 | S16: 0
A17: =Parameters!B14 -> A4132 | B17: =Parameters!B15 -> DIAN | C17: =Parameters!B16 -> Portal | D17: Total | E17: =SUM(E12:E16) -> 36768000 | F17: =SUM(F12:F16) -> 2467992000 | G17: =SUM(G12:G16) -> 240420000 | H17: =SUM(H12:H16) -> 322324500 | I17: =SUM(I12:I16) -> 412738500 | J17: =SUM(J12:J16) -> 412738500 | K17: =SUM(K12:K16) -> 412738500 | L17: =SUM(L12:L16) -> 194818500 | ... JP17: =SUM(JP12:JP16) -> 0
A23: Costos
A24: =A11 -> ID Hubspot | B24: =B11 -> Cliente | C24: =C11 -> Proyecto | D24: =D11 -> Item | E24: Total Costo | F24: =F11 -> 2025_08_Ago | G24: =G11 -> 2025_09_Sep | H24: =H11 -> 2025_10_Oct | I24: =I11 -> 2025_11_Nov | J24: =J11 -> 2025_12_Dic | K24: =K11 -> 2026_01_Ene | L24: =L11 -> 2026_02_Feb | M24: =M11 -> 2026_03_Mar | ... FZ24: =FZ11 -> 0
A25: =A12 -> A4132 | B25: =B12 -> DIAN | C25: =C12 -> Portal | D25: Costo Implementación | E25: =Total!G4 -> 13668571 | F25: 97722022 | G25: 97722022 | H25: 97722022 | I25: 97722022 | J25: 97722022 | K25: 97722022 | L25: 0 | M25: 0 | N25: 0 | O25: 0 | P25: 0 | Q25: 0 | R25: 0 | S25: 0
A26: =A13 -> A4132 | B26: =B13 -> DIAN | C26: =C13 -> Portal | D26: Costo Operación | E26: =Total!G6 -> 0 | F26: 0 | G26: 0 | H26: 31480920 | I26: 31480920 | J26: 31480920 | K26: 31480920 | L26: 31480920 | M26: 31480920 | N26: 31480920 | O26: 31480920 | P26: 31480920 | Q26: 31480920 | R26: 31480920 | S26: 31480920
A27: =A14 -> A4132 | B27: =B14 -> DIAN | C27: =C14 -> Portal | D27: Costo CS (Cloud Services) | E27: =Total!G5+Total!G7 -> 7263151.2 | F27: 0 | G27: 22500000 | H27: 22500000 | I27: 1.0471909e+08 | J27: 1.0471909e+08 | K27: 1.0471909e+08 | L27: 1.0471909e+08 | M27: 1.0471909e+08 | N27: 1.0471909e+08 | O27: 1.0471909e+08 | P27: 1.0471909e+08 | Q27: 1.0471909e+08 | R27: 1.0471909e+08 | S27: 1.0471909e+08
A28: =A15 -> A4132 | B28: =B15 -> DIAN | C28: =C15 -> Portal | D28: Costo SW (Software) | E28: =Total!G8 -> 0 | F28: 0 | G28: 0 | H28: 1170000 | I28: 1170000 | J28: 1170000 | K28: 1170000 | L28: 1170000 | M28: 1170000 | N28: 1170000 | O28: 1170000 | P28: 1170000 | Q28: 1170000 | R28: 1170000 | S28: 1170000
A29: A4132 | B29: DIAN | C29: Portal | D29: Other Vendors | E29: =Total!G9 -> 0 | F29: 1980000000 | G29: 0 | H29: 0 | I29: 0 | J29: 0 | K29: 0 | L29: 0 | M29: 0 | N29: 0 | O29: 0 | P29: 0 | Q29: 0 | R29: 0 | S29: 0
A30: =A17 -> A4132 | B30: =B17 -> DIAN | C30: =C17 -> Portal | D30: Costo Total | E30: =SUM(E25:E29) -> 20931723 | F30: =SUM(F25:F29) -> 2.077722e+09 | G30: =SUM(G25:G29) -> 1.2022202e+08 | H30: =SUM(H25:H29) -> 1.5287294e+08 | I30: =SUM(I25:I29) -> 2.3509203e+08 | J30: =SUM(J25:J29) -> 2.3509203e+08 | K30: =SUM(K25:K29) -> 2.3509203e+08 | L30: =SUM(L25:L29) -> 1.3737001e+08 | ... GH30: =SUM(GH25:GH29) -> 0
A33: Gross
A34: ID Hubspot | B34: Cliente | C34: Proyecto | D34: Item | E34: Total Gross | F34: =F11 -> 2025_08_Ago | G34: =G11 -> 2025_09_Sep | H34: =H11 -> 2025_10_Oct | I34: =I11 -> 2025_11_Nov | J34: =J11 -> 2025_12_Dic | K34: =K11 -> 2026_01_Ene | L34: =L11 -> 2026_02_Feb | M34: =M11 -> 2026_03_Mar | ... FZ34: =FZ11 -> 0
A35: =A12 -> A4132 | B35: =B12 -> DIAN | C35: =C12 -> Portal | D35: Gross Implementación | E35: =IFERROR(1-(E25/E12),0) -> 0.52795374 | F35: =IFERROR(1-(F25/F12),0) -> 0.55156928 | G35: =IFERROR(1-(G25/G12),0) -> 0.55156928 | H35: =IFERROR(1-(H25/H12),0) -> 0.55156928 | I35: =IFERROR(1-(I25/I12),0) -> 0.55156928 | J35: =IFERROR(1-(J25/J12),0) -> 0.55156928 | K35: =IFERROR(1-(K25/K12),0) -> 0.55156928 | L35: =IFERROR(1-(L25/L12),0) -> 0 | ... GV35: =IFERROR(1-(GV25/GV12),0) -> 0
A36: =A13 -> A4132 | B36: =B13 -> DIAN | C36: =C13 -> Portal | D36: Gross Operación | E36: =IFERROR(1-(E26/E13),0) -> 0 | F36: =IFERROR(1-(F26/F13),0) -> 0 | G36: =IFERROR(1-(G26/G13),0) -> 0 | H36: =IFERROR(1-(H26/H13),0) -> 0.55158259 | I36: =IFERROR(1-(I26/I13),0) -> 0.55158259 | J36: =IFERROR(1-(J26/J13),0) -> 0.55158259 | K36: =IFERROR(1-(K26/K13),0) -> 0.55158259 | L36: =IFERROR(1-(L26/L13),0) -> 0.55158259 | ... GV36: =IFERROR(1-(GV26/GV13),0) -> 0
A37: =A14 -> A4132 | B37: =B14 -> DIAN | C37: =C14 -> Portal | D37: Gross CS (Cloud Services) | E37: =IFERROR(1-(E27/E14),0) -> 0.070257143 | F37: =IFERROR(1-(F27/F14),0) -> 0 | G37: =IFERROR(1-(G27/G14),0) -> 0 | H37: =IFERROR(1-(H27/H14),0) -> 0 | I37: =IFERROR(1-(I27/I14),0) -> 0.072576555 | J37: =IFERROR(1-(J27/J14),0) -> 0.072576555 | K37: =IFERROR(1-(K27/K14),0) -> 0.072576555 | L37: =IFERROR(1-(L27/L14),0) -> 0.072576555 | ... GV37: =IFERROR(1-(GV27/GV14),0) -> 0
A38: =A15 -> A4132 | B38: =B15 -> DIAN | C38: =C15 -> Portal | D38: Gross SW (Software) | E38: =IFERROR(1-(E28/E15),0) -> 0 | F38: =IFERROR(1-(F28/F15),0) -> 0 | G38: =IFERROR(1-(G28/G15),0) -> 0 | H38: =IFERROR(1-(H28/H15),0) -> 0.9 | I38: =IFERROR(1-(I28/I15),0) -> 0.9 | J38: =IFERROR(1-(J28/J15),0) -> 0.9 | K38: =IFERROR(1-(K28/K15),0) -> 0.9 | L38: =IFERROR(1-(L28/L15),0) -> 0.9 | ... GV38: =IFERROR(1-(GV28/GV15),0) -> 0
A39: =A16 -> A4132 | B39: =B16 -> DIAN | C39: =C16 -> Portal | D39: Gross Other Vendors | E39: =IFERROR(1-(E29/E16),0) -> 0 | F39: =IFERROR(1-(F29/F16),0) -> 0.12002816 | G39: =IFERROR(1-(G29/G16),0) -> 0 | H39: =IFERROR(1-(H29/H16),0) -> 0 | I39: =IFERROR(1-(I29/I16),0) -> 0 | J39: =IFERROR(1-(J29/J16),0) -> 0 | K39: =IFERROR(1-(K29/K16),0) -> 0 | L39: =IFERROR(1-(L29/L16),0) -> 0 | ... GV39: =IFERROR(1-(GV29/GV16),0) -> 0
A40: =A17 -> A4132 | B40: =B17 -> DIAN | C40: =C17 -> Portal | D40: Gross Total | E40: =IFERROR(1-(E30/E17),0) -> 0.43070815 | F40: =IFERROR(1-(F30/F17),0) -> 0.15813259 | G40: =IFERROR(1-(G30/G17),0) -> 0.49994999 | H40: =IFERROR(1-(H30/H17),0) -> 0.52571727 | I40: =IFERROR(1-(I30/I17),0) -> 0.43040925 | J40: =IFERROR(1-(J30/J17),0) -> 0.43040925 | K40: =IFERROR(1-(K30/K17),0) -> 0.43040925 | L40: =IFERROR(1-(L30/L17),0) -> 0.2948821 | ... GV40: =IFERROR(1-(GV30/GV17),0) -> 0

Sheet Finance (Objetivo)
A1: ID Hubspot | B1: Cliente | C1: Proyecto
A2: =Parameters!B14 -> A4132 | B2: =Parameters!B15 -> DIAN | C2: =Parameters!B16 -> Portal
A4: Resumen
A5: Item | B5: Total | C5: Gross Margin | D5: Revenue Allocation | E5: 2025 | F5: 2026
A6: Implementación | B6: =B16 -> 1307520000 | C6: =IFERROR(1-(Finance!E25/Finance!E12),0) -> 0.52795374 | D6: =IFERROR((B6/$B$11),0) -> 0.22437066 | E6: 1089600000 | F6: 217920000
A7: Operación | B7: =B17 -> 842454000 | C7: =IFERROR(1-(Finance!E26/Finance!E13),0) -> 0 | D7: =IFERROR((B7/$B$11),0) -> 0.14456525 | E7: 210613500 | F7: 631840500
A8: CS (Cloud Services) | B8: =B18 -> 1287054000 | C8: =IFERROR(1-(Finance!E27/Finance!E14),0) -> 0.070257143 | D8: =IFERROR((B8/$B$11),0) -> 0.22085869 | E8: 270828000 | F8: 1016226000
A9: SW (Software) | B9: =B19 -> 140400000 | C9: =IFERROR(1-(Finance!E28/Finance!E15),0) -> 0 | D9: =IFERROR((B9/$B$11),0) -> 0.024092664 | E9: 35100000 | F9: 105300000
A10: Other Vendors | B10: =B20 -> 2250072000 | C10: =IFERROR(1-(Finance!E29/Finance!E16),0) -> 0 | D10: =IFERROR((B10/$B$11),0) -> 0.38611274 | E10: 2250072000 | F10: 0
A11: Total | B11: =B21 -> 5827500000 | C11: =IFERROR(1-(Finance!E30/Finance!E17),0) -> 0.43070815 | D11: =SUM(D6:D9) -> 0.61388726 | E11: =SUM(E6:E10) -> 3856213500 | F11: =SUM(F6:F10) -> 1971286500
A14: Total
A15: Item | B15: Total | C15: 2025_08_Ago | D15: 2025_09_Sep | E15: 2025_10_Oct | F15: 2025_11_Nov | G15: 2025_12_Dic | H15: 2026_01_Ene | I15: 2026_02_Feb | J15: 2026_03_Mar | K15: 2026_04_Abr | L15: 2026_05_May | M15: 2026_06_Jun | N15: 2026_07_Jul | O15: 2026_08_Ago | P15: 2026_09_Sep
A16: Implementación | B16: 1307520000 | C16: 217920000 | D16: 217920000 | E16: 217920000 | F16: 217920000 | G16: 217920000 | H16: 217920000 | I16: 0 | J16: 0 | K16: 0 | L16: 0 | M16: 0 | N16: 0 | O16: 0 | P16: 0
A17: Operación | B17: 842454000 | C17: 0 | D17: 0 | E17: 70204500 | F17: 70204500 | G17: 70204500 | H17: 70204500 | I17: 70204500 | J17: 70204500 | K17: 70204500 | L17: 70204500 | M17: 70204500 | N17: 70204500 | O17: 70204500 | P17: 70204500
A18: CS (Cloud Services) | B18: 1287054000 | C18: 0 | D18: 22500000 | E18: 22500000 | F18: 112914000 | G18: 112914000 | H18: 112914000 | I18: 112914000 | J18: 112914000 | K18: 112914000 | L18: 112914000 | M18: 112914000 | N18: 112914000 | O18: 112914000 | P18: 112914000
A19: SW (Software) | B19: 140400000 | C19: 0 | D19: 0 | E19: 11700000 | F19: 11700000 | G19: 11700000 | H19: 11700000 | I19: 11700000 | J19: 11700000 | K19: 11700000 | L19: 11700000 | M19: 11700000 | N19: 11700000 | O19: 11700000 | P19: 11700000
A20: Other Vendors | B20: 2250072000 | C20: 2250072000 | D20: 0 | E20: 0 | F20: 0 | G20: 0 | H20: 0 | I20: 0 | J20: 0 | K20: 0 | L20: 0 | M20: 0 | N20: 0 | O20: 0 | P20: 0
A21: Total | B21: 5827500000 | C21: 2467992000 | D21: 240420000 | E21: 322324500 | F21: 412738500 | G21: 412738500 | H21: 412738500 | I21: 194818500 | J21: 194818500 | K21: 194818500 | L21: 194818500 | M21: 194818500 | N21: 194818500 | O21: 194818500 | P21: 194818500 | Q21: 0 | R21: 0 | S21: 0 | T21: 0 | U21: 0 | V21: 0 | W21: 0 | X21: 0 | Y21: 0 | Z21: 0 | AA21: 0 | AB21: 0 | AC21: 0 | AD21: 0 | AE21: 0 | AF21: 0 | AG21: 0 | AH21: 0 | AI21: 0 | AJ21: 0 | AK21: 0 | AL21: 0 | AM21: 0 | AN21: 0 | AO21: 0 | AP21: 0 | AQ21: 0 | AR21: 0 | AS21: 0 | AT21: 0 | AU21: 0 | AV21: 0 | AW21: 0 | AX21: 0 | AY21: 0 | AZ21: 0 | BA21: 0 | BB21: 0 | BC21: 0 | BD21: 0 | BE21: 0 | BF21: 0 | BG21: 0 | BH21: 0 | BI21: 0 | BJ21: 0 | BK21: 0 | BL21: 0 | BM21: 0 | BN21: 0 | BO21: 0 | BP21: 0 | BQ21: 0 | BR21: 0 | BS21: 0 | BT21: 0 | BU21: 0 | BV21: 0 | BW21: 0 | BX21: 0 | BY21: 0 | BZ21: 0 | CA21: 0 | CB21: 0 | CC21: 0 | CD21: 0 | CE21: 0 | CF21: 0 | CG21: 0 | CH21: 0 | CI21: 0 | CJ21: 0 | CK21: 0 | CL21: 0 | CM21: 0 | CN21: 0 | CO21: 0 | CP21: 0 | CQ21: 0 | CR21: 0 | CS21: 0 | CT21: 0 | CU21: 0 | CV21: 0 | CW21: 0 | CX21: 0 | CY21: 0 | CZ21: 0 | DA21: 0 | DB21: 0 | DC21: 0 | DD21: 0 | DE21: 0 | DF21: 0 | DG21: 0 | DH21: 0 | DI21: 0 | DJ21: 0 | DK21: 0 | DL21: 0 | DM21: 0 | DN21: 0 | DO21: 0 | DP21: 0 | DQ21: 0 | DR21: 0 | DS21: 0 | DT21: 0 | DU21: 0 | DV21: 0 | DW21: 0 | DX21: 0 | DY21: 0 | DZ21: 0 | EA21: 0 | EB21: 0 | EC21: 0 | ED21: 0 | EE21: 0 | EF21: 0 | EG21: 0 | EH21: 0 | EI21: 0 | EJ21: 0 | EK21: 0 | EL21: 0 | EM21: 0 | EN21: 0 | EO21: 0 | EP21: 0 | EQ21: 0 | ER21: 0 | ES21: 0 | ET21: 0 | EU21: 0 | EV21: 0 | EW21: 0 | EX21: 0 | EY21: 0 | EZ21: 0 | FA21: 0 | FB21: 0 | FC21: 0 | FD21: 0 | FE21: 0 | FF21: 0 | FG21: 0 | FH21: 0 | FI21: 0 | FJ21: 0 | FK21: 0 | FL21: 0 | FM21: 0 | FN21: 0 | FO21: 0 | FP21: 0 | FQ21: 0 | FR21: 0 | FS21: 0 | FT21: 0 | FU21: 0 | FV21: 0 | FW21: 0 | FX21: 0 | FY21: 0 | FZ21: 0 | GA21: 0 | GB21: 0 | GC21: 0 | GD21: 0 | GE21: 0 | GF21: 0 | GG21: 0 | GH21: 0 | GI21: 0 | GJ21: 0 | GK21: 0 | GL21: 0 | GM21: 0 | GN21: 0 | GO21: 0 | GP21: 0 | GQ21: 0 | GR21: 0 | GS21: 0 | GT21: 0 | GU21: 0 | GV21: 0 | GW21: 0 | GX21: 0 | GY21: 0 | GZ21: 0 | HA21: 0 | HB21: 0 | HC21: 0 | HD21: 0 | HE21: 0 | HF21: 0 | HG21: 0 | HH21: 0 | HI21: 0 | HJ21: 0 | HK21: 0 | HL21: 0 | HM21: 0 | HN21: 0 | HO21: 0 | HP21: 0 | HQ21: 0 | HR21: 0 | HS21: 0 | HT21: 0 | HU21: 0 | HV21: 0 | HW21: 0 | HX21: 0 | HY21: 0 | HZ21: 0 | IA21: 0 | IB21: 0 | IC21: 0 | ID21: 0 | IE21: 0 | IF21: 0 | IG21: 0 | IH21: 0 | II21: 0 | IJ21: 0 | IK21: 0 | IL21: 0 | IM21: 0 | IN21: 0 | IO21: 0 | IP21: 0 | IQ21: 0 | IR21: 0 | IS21: 0 | IT21: 0 | IU21: 0 | IV21: 0 | IW21: 0 | IX21: 0 | IY21: 0 | IZ21: 0 | JA21: 0 | JB21: 0 | JC21: 0 | JD21: 0 | JE21: 0 | JF21: 0 | JG21: 0 | JH21: 0 | JI21: 0 | JJ21: 0 | JK21: 0 | JL21: 0 | JM21: 0
A23: 2025
A24: Item | B24: Total | C24: 2025_08_Ago | D24: 2025_09_Sep | E24: 2025_10_Oct | F24: 2025_11_Nov | G24: 2025_12_Dic | H24: 2025_12_Dic
A25: Implementación | B25: 1089600000 | C25: 217920000 | D25: 217920000 | E25: 217920000 | F25: 217920000 | G25: 217920000 | H25: 305673000
A26: Operación | B26: 210613500 | C26: 0 | D26: 0 | E26: 70204500 | F26: 70204500 | G26: 70204500 | H26: 257710500
A27: CS (Cloud Services) | B27: 270828000 | C27: 0 | D27: 22500000 | E27: 22500000 | F27: 112914000 | G27: 112914000 | H27: 112914000
A28: SW (Software) | B28: 35100000 | C28: 0 | D28: 0 | E28: 11700000 | F28: 11700000 | G28: 11700000 | H28: 11700000
A29: Other Vendors | B29: 2250072000 | C29: 2250072000 | D29: 0 | E29: 0 | F29: 0 | G29: 0 | H29: 0
A30: Total | B30: 3856213500 | C30: 2467992000 | D30: 240420000 | E30: 322324500 | F30: 412738500 | G30: 412738500 | H30: 687997500
A32: 2026
A33: Item | B33: Total | C33: 2026_01_Ene | D33: 2026_02_Feb | E33: 2026_03_Mar | F33: 2026_04_Abr | G33: 2026_05_May | H33: 2026_06_Jun | I33: 2026_07_Jul | J33: 2026_08_Ago | K33: 2026_09_Sep
A34: Implementación | B34: 217920000 | C34: 217920000 | D34: 0 | E34: 0 | F34: 0 | G34: 0 | H34: 0 | I34: 0 | J34: 0 | K34: 0
A35: Operación | B35: 631840500 | C35: 70204500 | D35: 70204500 | E35: 70204500 | F35: 70204500 | G35: 70204500 | H35: 70204500 | I35: 70204500 | J35: 70204500 | K35: 70204500
A36: CS (Cloud Services) | B36: 1016226000 | C36: 112914000 | D36: 112914000 | E36: 112914000 | F36: 112914000 | G36: 112914000 | H36: 112914000 | I36: 112914000 | J36: 112914000 | K36: 112914000
A37: SW (Software) | B37: 105300000 | C37: 11700000 | D37: 11700000 | E37: 11700000 | F37: 11700000 | G37: 11700000 | H37: 11700000 | I37: 11700000 | J37: 11700000 | K37: 11700000
A38: Other Vendors | B38: 0 | C38: 0 | D38: 0 | E38: 0 | F38: 0 | G38: 0 | H38: 0 | I38: 0 | J38: 0 | K38: 0
A39: Total | B39: 1971286500 | C39: 412738500 | D39: 194818500 | E39: 194818500 | F39: 194818500 | G39: 194818500 | H39: 194818500 | I39: 194818500 | J39: 194818500 | K39: 194818500
A41: 2027
